Workbook
Name __k10003: [3]L100100!#REF!
Name _121_201_103: #REF!
Name _121_201_103: #REF!
Name _ABR1: [4]ABR!$A$3:$K$598
Name _ABR2: [4]ABR!$A$603:$N$612
Name _ABR3: [4]ABR!$A$617:$O$637
Name _AGO1: [4]AGO!$A$3:$K$719
Name _AGO2: [4]AGO!$A$724:$N$735
Name _AGO3: [4]AGO!$A$740:$O$791
Name _CUM1: #REF!
Name _CUM2: #REF!
Name _CUM3: #REF!
Name _CUM4: #REF!
Name _CUM5: #REF!
Name _CUM6: #REF!
Name _DEZ1: [4]DEZ!$A$3:$K$5
Name _DEZ2: [4]DEZ!$A$10:$N$12
Name _DEZ3: [4]DEZ!$A$17:$O$19
Name _FEB99: [5]PLANILHA!$A$3:$GC$12
Name _FEV1: [4]FEV!$A$3:$K$447
Name _FEV2: [4]FEV!$A$452:$N$460
Name _FEV3: [4]FEV!$A$465:$O$476
Name _JAN1: [4]JAN!$A$3:$K$434
Name _JAN2: [4]JAN!$A$439:$N$449
Name _JAN3: [4]JAN!$A$454:$O$466
Name _JUL1: [4]JUL!$A$3:$K$522
Name _JUL2: [4]JUL!$A$527:$N$537
Name _JUL3: [4]JUL!$A$542:$O$565
Name _JUN1: [4]JUN!$A$3:$K$532
Name _JUN2: [4]JUN!$A$537:$N$548
Name _JUN3: [4]JUN!$A$554:$O$581
Name _k10003: [6]L100100!#REF!
Name _MAI1: [4]MAI!$A$3:$K$495
Name _MAI2: [4]MAI!$A$500:$N$509
Name _MAI3: [4]MAI!$A$514:$O$523
Name _MAR1: [4]MAR!$A$3:$K$672
Name _MAR2: [4]MAR!$A$677:$N$680
Name _MAR3: [4]MAR!$A$685:$O$698
Name _NOV1: [4]NOV!$A$3:$K$5
Name _NOV2: [4]NOV!$A$10:$N$12
Name _NOV3: [4]NOV!$A$17:$O$19
Name _OBS1: Capa!$B$22
Name _OBS1: #REF!
Name _OBS2: Capa!#REF!
Name _OBS2: #REF!
Name _OBS3: Capa!#REF!
Name _OBS3: #REF!
Name _OBS4: Capa!$B$23
Name _OBS4: #REF!
Name _OBS5: Capa!$B$24
Name _OBS5: #REF!
Name _OBS6: Capa!$B$25
Name _OBS6: #REF!
Name _OUT1: [4]OUT!$A$3:$K$5
Name _OUT2: [4]OUT!$A$10:$N$12
Name _OUT3: [4]OUT!$A$17:$O$19
Name _PL1: #REF!
Name _PRT1: [4]VOUCHER!$V$32
Name _PRT10: [4]VOUCHER!$V$356
Name _PRT11: [4]VOUCHER!$V$392

Sheet Parametros
A1: Pergunta 01 : Da Conta ? | B1: 21510050
A2: Pergunta 02 : Ate Conta ? | B2: 21510050
A3: Pergunta 03 : Da Data ? | B3: 01/01/2010
A4: Pergunta 04 : Ate a Data ? | B4: 30/06/2026
A5: Pergunta 05 : Moeda ? | B5: 01
A6: Pergunta 06 : Tipo de Saldo ? | B6: 1
A7: Pergunta 07 : Cod. Config. Livros ?
A8: Pergunta 08 : Tipo Relatorio ? | B8: Analitico
A9: Pergunta 09 : Impr. Cta S/ Movim ? | B9: Nao
A10: Pergunta 10 : Junta C.C. Contabil ? | B10: Nao
A11: Pergunta 11 : Impr Cod Conta ? | B11: Normal
A12: Pergunta 12 : Imprime C.C. Extra ? | B12: Sim
A13: Pergunta 13 : Do Centro de Custo ?
A14: Pergunta 14 : Ate Centro de Custo ? | B14: ZZZZZZZZZ
A15: Pergunta 15 : Imprime Item Contab ? | B15: Nao
A16: Pergunta 16 : Do Item Contabil ?
A17: Pergunta 17 : Ate Item Contabil ? | B17: ZZZZZZZZZ
A18: Pergunta 18 : Imprime Classe Vlr ? | B18: Nao
A19: Pergunta 19 : Da Classe de Valor ?
A20: Pergunta 20 : Ate Classe de Valor ? | B20: ZZZZZZZZZ
A21: Pergunta 21 : Salta Folha por Cta ? | B21: Nao
A22: Pergunta 22 : Folha Inicial ? | B22: 1
A23: Pergunta 23 : Folha Final ? | B23: 999999
A24: Pergunta 24 : Folha ao Reiniciar ? | B24: 1
A25: Pergunta 25 : Impr Cod C.Custo ? | B25: Normal
A26: Pergunta 26 : Impr Cod Item ? | B26: Normal
A27: Pergunta 27 : Impr Cod Cl.Valor ? | B27: Normal
A28: Pergunta 28 : Imprime Total Geral ? | B28: Sim
A29: Pergunta 29 : Imprime ? | B29: So Livro
A30: Pergunta 30 : Imprime Valor 0,00 ? | B30: Sim
A31: Pergunta 31 : Salta linha entre contas ? | B31: Nao
A32: Pergunta 32 : Num.linhas p/ o Razao ? | B32: 90
A33: Pergunta 33 : Sld.Ant.Nivel ? | B33: Conta
A34: Pergunta 34 : Descrição na Moeda ? | B34: 01
A35: Pergunta 35 : Cons.Tamanho Total das Entid ? | B35: Sim
A36: Pergunta 36 : Seleciona Filiais ? | B36: Sim
A37: Pergunta 37 : Imprimir Cabeçalho ? | B37: Sim
A38: Pergunta 38 : Filtro de Entidades ? | B38: De/Até
A39: Pergunta 39 : Range de Conta ?
A40: Pergunta 40 : Range de Centro de Custo ?
...

Sheet 01.Razão (2)
L2: 225387.67
M5: =SUBTOTAL(9,M7:M120) -> -329237.8
B6: Período | C6: Conta | D6: Conta + Descrição | E6: Data | F6: LOTE/SUB/DOC/LINHA | G6: HISTORICO | H6: C/PARTIDA | I6: FL | J6: C CUSTO | K6: DEBITO | L6: CREDITO | M6: Valor | N6: Obs.
B7: 2021 | C7: =MID(D7,1,12) -> 2.1.1.05.000 | D7: 2.1.1.05.0005 - PROVISAO BONUS A PAGAR | E7: 44316 | F7: 000001001000012001 | G7: PROVISAO DE BONUS MES MARÇO E ABRIL | H7: 4.1.1.01.0026 | I7: 0301 | K7: 0 | L7: 40500 | M7: -40500 | N7: Efeito zero
B8: 2021 | C8: =MID(D8,1,12) -> 2.1.1.05.000 | D8: 2.1.1.05.0005 - PROVISAO BONUS A PAGAR | E8: 44347 | F8: 001010001000001001 | G8: PROVISAO DE BONUS MES MAIO-21 | H8: 4.1.1.01.0026 | I8: 0301 | K8: 0 | L8: 27000 | M8: -27000 | N8: Efeito zero
B9: 2021 | C9: =MID(D9,1,12) -> 2.1.1.05.000 | D9: 2.1.1.05.0005 - PROVISAO BONUS A PAGAR | E9: 44377 | F9: 000001001000001005 | G9: PROVISAO DE BONUS JUN 2021 | H9: 4.1.1.01.0026 | I9: 0301 | K9: 0 | L9: 27000 | M9: -27000 | N9: Efeito zero
B10: 2021 | C10: =MID(D10,1,12) -> 2.1.1.05.000 | D10: 2.1.1.05.0005 - PROVISAO BONUS A PAGAR | E10: 44407 | F10: 000001001000008001 | G10: PROV PROVISAO DE BONUS | H10: 4.1.1.01.0026 | I10: 0301 | K10: 0 | L10: 27000 | M10: -27000 | N10: Efeito zero
B11: 2021 | C11: =MID(D11,1,12) -> 2.1.1.05.000 | D11: 2.1.1.05.0005 - PROVISAO BONUS A PAGAR | E11: 44439 | F11: 000001001000001001 | G11: PROV PROVISAO DE BONUS | H11: 4.1.1.01.0026 | I11: 0301 | K11: 0 | L11: 27000 | M11: -27000 | N11: Efeito zero
B12: 2021 | C12: =MID(D12,1,12) -> 2.1.1.05.000 | D12: 2.1.1.05.0005 - PROVISAO BONUS A PAGAR | E12: 44467 | F12: 000001001000005001 | G12: PROV PROVISAO DE BONUS | H12: 4.1.1.01.0026 | I12: 0301 | K12: 0 | L12: 27000 | M12: -27000 | N12: Efeito zero
B13: 2021 | C13: =MID(D13,1,12) -> 2.1.1.05.000 | D13: 2.1.1.05.0005 - PROVISAO BONUS A PAGAR | E13: 44498 | F13: 000001001000002001 | G13: PROV PROVISAO DE BONUS | H13: 4.1.1.01.0026 | I13: 0301 | K13: 0 | L13: 27000 | M13: -27000 | N13: Efeito zero
B14: 2021 | C14: =MID(D14,1,12) -> 2.1.1.05.000 | D14: 2.1.1.05.0005 - PROVISAO BONUS A PAGAR | E14: 44529 | F14: 000001001000002001 | G14: PROV PROVISAO DE BONUS | H14: 4.1.1.01.0026 | I14: 0301 | K14: 0 | L14: 27000 | M14: -27000 | N14: Efeito zero
B15: 2021 | C15: =MID(D15,1,12) -> 2.1.1.05.000 | D15: 2.1.1.05.0005 - PROVISAO BONUS A PAGAR | E15: 44560 | F15: 000001001000002001 | G15: PROV PROVISAO DE BONUS | H15: 4.1.1.01.0026 | I15: 0301 | K15: 0 | L15: 27000 | M15: -27000 | N15: Efeito zero
B16: 2021 | C16: 2.1.1.05.0005 | D16: 2.1.1.05.0005 - PROVISAO BONUS A PAGAR | E16: 44227 | F16: 000001001000014001 | G16: PROV BONUS A PAGAR ACIONISTA | H16: 4.1.1.01.0026 | I16: 0301 | K16: 0 | L16: 22500 | M16: -22500 | N16: Efeito zero
B17: 2021 | C17: =MID(D17,1,12) -> 2.1.1.05.000 | D17: 2.1.1.05.0005 - PROVISAO BONUS A PAGAR | E17: 44255 | F17: 000001001000001001 | G17: PROV BONUS A PAGAR ACIONISTA | H17: 4.1.1.01.0026 | I17: 0301 | K17: 0 | L17: 22500 | M17: -22500 | N17: Efeito zero
B18: 2021 | C18: =MID(D18,1,12) -> 2.1.1.05.000 | D18: 2.1.1.05.0005 - PROVISAO BONUS A PAGAR | E18: 44286 | F18: 000001001000014001 | G18: PROV BONUS A PAGAR ACIONISTA | H18: 4.1.1.01.0026 | I18: 0301 | K18: 0 | L18: 22500 | M18: -22500 | N18: Efeito zero
B19: 2023 | C19: =MID(D19,1,12) -> 2.1.1.05.000 | D19: 2.1.1.05.0005 - PROVISAO BONUS A PAGAR | E19: 45016 | F19: 000001001000016001 | G19: PROV BONUS | H19: 4.1.1.01.0026 | I19: 0301 | K19: 0 | L19: 1 | M19: =L19*-1 -> -1
B20: 2024 | C20: =MID(D20,1,12) -> 2.1.1.05.000 | D20: 2.1.1.05.0005 - PROVISAO BONUS A PAGAR | E20: 45412 | F20: 000001001000012001 | G20: VLR AJUSTE PROVISAO FILIAL | H20: 4.1.1.01.0026 | I20: 0301 | J20: 0.3.8.000018 | K20: 639.42 | L20: 0 | M20: 639.42 | N20: Efeito zero
B21: 2024 | C21: =MID(D21,1,12) -> 2.1.1.05.000 | D21: 2.1.1.05.0005 - PROVISAO BONUS A PAGAR | E21: 45412 | F21: 000001001000009001 | G21: VLR AJUSTE PROVISAO FILIAL | H21: 4.1.1.01.0026 | I21: 0302 | J21: 0.3.7.000007 | K21: 0 | L21: 639.42 | M21: =L21*-1 -> -639.42 | N21: Efeito zero
B22: 2025 | C22: =MID(D22,1,12) -> 2.1.1.05.000 | D22: 2.1.1.05.0005 - PROVISAO BONUS A PAGAR | E22: 45809 | F22: 000001001000007001 | G22: PROVISÃO BONUS-JUN/25 | H22: 4.1.1.01.0026 | I22: 0301 | K22: 0 | L22: 1408 | M22: =L22*-1 -> -1408
B23: 2026 | C23: =MID(D23,1,12) -> 2.1.1.05.000 | D23: 2.1.1.05.0005 - PROVISAO BONUS A PAGAR | E23: 46203 | F23: WN2026001000004004 | G23: RECLAS.VLR FOPG 402 - DESCONTO DIVERSOS | H23: 4.4.1.01.0011 | I23: 0302 | J23: 0.3.2.000001 | K23: 0 | L23: 4159.93 | M23: =L23*-1 -> -4159.93
B24: 2026 | C24: =MID(D24,1,12) -> 2.1.1.05.000 | D24: 2.1.1.05.0005 - PROVISAO BONUS A PAGAR | E24: 46142 | F24: WN2026001000004006 | G24: REV.VLR FOPG 313 - PREMIO | H24: 3.1.1.04.0020 | I24: 0302 | J24: 0.3.7.000007 | K24: 4427.88 | L24: 0 | M24: 4427.88
B25: 2026 | C25: =MID(D25,1,12) -> 2.1.1.05.000 | D25: 2.1.1.05.0005 - PROVISAO BONUS A PAGAR | E25: 46203 | F25: WN2026001000004001 | G25: RECLAS.VLR FOPG 313 - PREMIO | H25: 3.1.1.04.0020 | I25: 0302 | J25: 0.3.8.000025 | K25: 5737.83 | L25: 0 | M25: 5737.83
B26: 2026 | C26: =MID(D26,1,12) -> 2.1.1.05.000 | D26: 2.1.1.05.0005 - PROVISAO BONUS A PAGAR | E26: 46142 | F26: WN2026001000004001 | G26: REV.VLR FOPG 402 - DESCONTO DIVERSOS | H26: 4.4.1.01.0011 | I26: 0302 | K26: 0 | L26: 6111.41 | M26: =L26*-1 -> -6111.41
B27: 2026 | C27: =MID(D27,1,12) -> 2.1.1.05.000 | D27: 2.1.1.05.0005 - PROVISAO BONUS A PAGAR | E27: 46142 | F27: WN2026001000004005 | G27: REV.VLR FOPG 313 - PREMIO | H27: 3.1.1.04.0020 | I27: 0302 | K27: 7176.11 | L27: 0 | M27: 7176.11
B28: 2023 | C28: =MID(D28,1,12) -> 2.1.1.05.000 | D28: 2.1.1.05.0005 - PROVISAO BONUS A PAGAR | E28: 45107 | F28: 000001001000007002 | G28: VLR PROVISAO BONUS | H28: 4.1.1.01.0026 | I28: 0301 | K28: 0 | L28: 7639 | M28: =L28*-1 -> -7639
B29: 2022 | C29: =MID(D29,1,12) -> 2.1.1.05.000 | D29: 2.1.1.05.0005 - PROVISAO BONUS A PAGAR | E29: 44621 | F29: 000001001000007001 | G29: VLR FOL 280220222 EDUARDO DE SETTIALVES | H29: 2.1.1.01.0002 | I29: 0301 | K29: 0 | L29: 8000 | M29: =L29*-1 -> -8000 | N29: Efeito zero
B30: 2022 | C30: =MID(D30,1,12) -> 2.1.1.05.000 | D30: 2.1.1.05.0005 - PROVISAO BONUS A PAGAR | E30: 44624 | F30: 008850001000019003 | G30: VLR PG FOL 280220222- EDUARDO DE SETTIALVES PRO - LABORE | H30: 1.1.1.02.0010 | I30: 0301 | K30: 8000 | L30: 0 | M30: 8000 | N30: Efeito zero
B31: 2022 | C31: =MID(D31,1,12) -> 2.1.1.05.000 | D31: 2.1.1.05.0005 - PROVISAO BONUS A PAGAR | E31: 44651 | F31: 008850001000015001 | G31: VLR FOL 310320222 EDUARDO DE SETTIALVES | H31: 4.1.1.01.0002 | I31: 0301 | K31: 0 | L31: 8000 | M31: =L31*-1 -> -8000 | N31: Efeito zero
B32: 2026 | C32: =MID(D32,1,12) -> 2.1.1.05.000 | D32: 2.1.1.05.0005 - PROVISAO BONUS A PAGAR | E32: 46142 | F32: WN2026001000004002 | G32: REV.VLR FOPG 402 - DESCONTO DIVERSOS | H32: 4.4.1.01.0011 | I32: 0302 | K32: 0 | L32: 8769.49 | M32: =L32*-1 -> -8769.49
B33: 2024 | C33: =MID(D33,1,12) -> 2.1.1.05.000 | D33: 2.1.1.05.0005 - PROVISAO BONUS A PAGAR | E33: 45626 | F33: 000001001000002002 | G33: VLR PROVISAO DE BONUS | H33: 4.1.1.01.0026 | I33: 0301 | K33: 0 | L33: 10257 | M33: =L33*-1 -> -10257
B34: 2024 | C34: =MID(D34,1,12) -> 2.1.1.05.000 | D34: 2.1.1.05.0005 - PROVISAO BONUS A PAGAR | E34: 45657 | F34: 99999L001000001001 | G34: PROVISÃO BONUS | H34: 4.1.1.01.0026 | I34: 0301 | K34: 0 | L34: 10257 | M34: =L34*-1 -> -10257
B35: 2024 | C35: =MID(D35,1,12) -> 2.1.1.05.000 | D35: 2.1.1.05.0005 - PROVISAO BONUS A PAGAR | E35: 45566 | F35: 000001001000001002 | G35: VLR PROVISAO DE BONUS | H35: 4.1.1.01.0026 | I35: 0301 | K35: 0 | L35: 11967 | M35: =L35*-1 -> -11967
B36: 2024 | C36: =MID(D36,1,12) -> 2.1.1.05.000 | D36: 2.1.1.05.0005 - PROVISAO BONUS A PAGAR | E36: 45626 | F36: 000001001000001001 | G36: VLR PREVISAO BONUS | H36: 4.1.1.01.0026 | I36: 0302 | K36: 0 | L36: 12740 | M36: =L36*-1 -> -12740
B37: 2024 | C37: =MID(D37,1,12) -> 2.1.1.05.000 | D37: 2.1.1.05.0005 - PROVISAO BONUS A PAGAR | E37: 45657 | F37: 000001001000008001 | G37: VLR PREVISAO BONUS | H37: 4.1.1.01.0026 | I37: 0302 | K37: 0 | L37: 12740 | M37: =L37*-1 -> -12740
B38: 2024 | C38: =MID(D38,1,12) -> 2.1.1.05.000 | D38: 2.1.1.05.0005 - PROVISAO BONUS A PAGAR | E38: 45412 | F38: 000001001000007003 | G38: 313 - PRÊMIO | H38: 3.1.1.04.0020 | I38: 0302 | K38: 13393.18 | L38: 0 | M38: 13393.18
B39: 2023 | C39: =MID(D39,1,12) -> 2.1.1.05.000 | D39: 2.1.1.05.0005 - PROVISAO BONUS A PAGAR | E39: 45291 | F39: 000001001000006002 | G39: VLR PROVISAO BONUS | H39: 4.1.1.01.0026 | I39: 0301 | K39: 14960 | L39: 0 | M39: 14960
B40: 2024 | C40: =MID(D40,1,12) -> 2.1.1.05.000 | D40: 2.1.1.05.0005 - PROVISAO BONUS A PAGAR | E40: 45412 | F40: 000001001000015001 | G40: VLR PROV BONUS REF 2023 | H40: 4.1.1.01.0026 | I40: 0301 | J40: 0.3.3.000004 | K40: 0 | L40: 17988.02 | M40: =L40*-1 -> -17988.02
B41: 2024 | C41: =MID(D41,1,12) -> 2.1.1.05.000 | D41: 2.1.1.05.0005 - PROVISAO BONUS A PAGAR | E41: 45412 | F41: 000001001000007006 | G41: 313 - PRÊMIO | H41: 4.2.1.01.0020 | I41: 0302 | J41: 0.3.5.000004 | K41: 18052.65 | L41: 0 | M41: 18052.65
B42: 2026 | C42: =MID(D42,1,12) -> 2.1.1.05.000 | D42: 2.1.1.05.0005 - PROVISAO BONUS A PAGAR | E42: 46142 | F42: WN2026001000004003 | G42: REV.VLR FOPG 402 - DESCONTO DIVERSOS | H42: 4.4.1.01.0011 | I42: 0302 | K42: 0 | L42: 20828.18 | M42: =L42*-1 -> -20828.18
B43: 2026 | C43: =MID(D43,1,12) -> 2.1.1.05.000 | D43: 2.1.1.05.0005 - PROVISAO BONUS A PAGAR | E43: 46173 | F43: WN2026001000003003 | G43: REV.VLR FOPG 402 - DESCONTO DIVERSOS | H43: 4.4.1.01.0011 | I43: 0302 | J43: 0.3.2.000001 | K43: 0 | L43: 20828.18 | M43: =L43*-1 -> -20828.18
...

Sheet Capa
D2: SIGLA | E2: EMPRESA | J2: Emissão
D3: 01101 | E3: AMBAR TECH | J3: =TODAY() -> 46220
D4: GRUPO CONTÁBIL | E4: DESCRIÇÃO DO GRUPO | J4: PERIODO
J5: jun/26
D6: 2.1.5.00.000 | E6: OUTRAS OBRIGACOES
B9: Conta | C9: Descrição da Conta | G9: Balancete | H9: Relatorio Auxiliar | I9: Diferença
B10: 2.1.5.10.050 | C10: =_xlfn.XLOOKUP(B10,'00.Balancete'!E:E,'00.Balancete'!F:F) -> #N/A | G10: =-SUMIFS('00.Balancete'!$N:$N,'00.Balancete'!$E:$E,Capa!$B10) -> 0 | H10: ='02.Suporte'!Q7 -> 595920 | I10: =G10-H10 -> -595920
B13: DIFERENÇA ( 1 ) - ( 2 ) = ( 3 ) | G13: =SUM(G10:G10) -> 0 | H13: =SUM(H10:H10) -> 595920 | I13: =SUM(I10:I11) -> -595920
B15: COMPOSIÇÃO DA DIFERENÇA
B17: DATA | C17: DIFERENÇAS IDENTIFICADAS NA CONTABILIDADE | G17: Status | H17: Conta Débito | I17: Conta Crédito | J17: VALOR
B18: 45291 | C18: Saldo baixado a maior referente a provisão de Bônus - 2023 | H18: 5.1.3.80.140 | I18: 2.1.5.10.050 | J18: =-SUMIFS('03.Conciliação'!$E:$E,'03.Conciliação'!$F:$F,Capa!$C18) -> 0
B19: 45657 | C19: Saldo em aberto referente a Provisão de Bônus - 2024 | H19: 2.1.5.10.050 | I19: 5.1.3.80.140 | J19: =-SUMIFS('03.Conciliação'!$E:$E,'03.Conciliação'!$F:$F,Capa!$C19) -> 0
B20: 46022 | C20: Saldo em aberto referente a Provisão de Bônus - 2025 | H20: 2.1.5.10.050 | I20: 5.1.3.80.140 | J20: =-SUMIFS('03.Conciliação'!$E:$E,'03.Conciliação'!$F:$F,Capa!$C20) -> 0
B22: TOTAL ( 4 ) | J22: =SUM(J18:J21) -> 0
B24: DATA | C24: DIFERENÇAS IDENTIFICADAS NO RELATÓRIO | G24: Status | H24: Conta Débito | I24: Conta Crédito | J24: VALOR
J27: =IF(G27=0," ",IF(G27<0,"C","D"))
B28: TOTAL ( 5 ) | J28: =SUM(J25:J27) -> 0
B30: DIFERENÇA A IDENITIFICAR ( 3 ) - ( 4 ) - ( 5 ) | J30: =I13-J22-J28 -> -595920
B32: OBSERVAÇÕES: | E32: Prepado por : | G32: Revisado por: | H32: Aprovado por:
E33: Willian Nascimento | G33: Willian Nascimento
E34: =J3 -> 46220 | G34: 46204

Sheet 00.Balancete
M1: Ativo | N1: =SUMIFS($N$8:$N$407,$C$8:$C$407,$M1) -> 53511864
M2: Passivo | N2: =SUMIFS($N$8:$N$407,$C$8:$C$407,$M2) -> -1.2466241e+08
M3: Resultado | N3: =SUMIFS($N$8:$N$407,$C$8:$C$407,$M3) -> 7940390.2
M4: Check | N4: =SUM(N1:N3) -> -63210158
M6: =SUBTOTAL(9,M8:M407) -> -2.7677743e-08 | N6: =SUBTOTAL(9,N8:N407) -> -1.1916563e-07
B7: Período | C7: Classe | D7: Tipo | E7: Conta | F7: Descricao | G7: 31.12.25 | I7: DB | J7: CR | K7: 30.06.26 | M7: =G7 -> 31.12.25 | N7: =K7 -> 30.06.26 | O7: Obs.
B8: jun/26 | D8: =IF(MID(E8,10,3)="000","Sintetica","") -> Sintetica | E8: 1.0.0.00.0000 | F8: ATIVO | G8: 23463932 | H8: D | I8: 5841042 | J8: 5685303.1 | K8: 23619671 | L8: D | M8: =IF(H8="D",G8,-G8) -> 23463932 | N8: =IF(L8="D",K8,-K8) -> 23619671
B9: jun/26 | D9: =IF(MID(E9,10,3)="000","Sintetica","") -> Sintetica | E9: 1.1.0.00.0000 | F9: ATIVO CIRCULANTE | G9: 21423978 | H9: D | I9: 5818427 | J9: 5630446 | K9: 21611959 | L9: D | M9: =IF(H9="D",G9,-G9) -> 21423978 | N9: =IF(L9="D",K9,-K9) -> 21611959
B10: jun/26 | D10: =IF(MID(E10,10,3)="000","Sintetica","") -> Sintetica | E10: 1.1.1.00.0000 | F10: DISPONIVEL | G10: 1931841.1 | H10: D | I10: 4018479.6 | J10: 4225853.2 | K10: 1724467.5 | L10: D | M10: =IF(H10="D",G10,-G10) -> 1931841.1 | N10: =IF(L10="D",K10,-K10) -> 1724467.5
B11: jun/26 | D11: =IF(MID(E11,10,3)="000","Sintetica","") -> Sintetica | E11: 1.1.1.02.0000 | F11: BANCOS CONTA MOVIMENTO | G11: 782820.75 | H11: D | I11: 4018408.1 | J11: 4225167.1 | K11: 576061.72 | L11: D | M11: =IF(H11="D",G11,-G11) -> 782820.75 | N11: =IF(L11="D",K11,-K11) -> 576061.72
B12: jun/26 | C12: =IF(MID(E12,1,1)="1","Ativo",IF(MID(E12,1,1)="2","Passivo","Resultado")) -> Ativo | D12: =IF(MID(E12,10,3)="000","Sintetica","") | E12: 1.1.1.02.0010 | F12: BRADESCO S/A - SMART PODS | G12: 0 | I12: 1530143.8 | J12: 1530143.8 | K12: 0 | M12: =IF(H12="D",G12,-G12) -> 0 | N12: =IF(L12="D",K12,-K12) -> 0
B13: jun/26 | D13: =IF(MID(E13,10,3)="000","Sintetica","") | E13: 1.1.1.02.0011 | F13: ITAU S/A - SMART PODS | G13: 72.52 | H13: D | I13: 673.68 | J13: 1108.89 | K13: 362.69 | L13: C | M13: =IF(H13="D",G13,-G13) -> 72.52 | N13: =IF(L13="D",K13,-K13) -> -362.69
B14: jun/26 | C14: =IF(MID(E14,1,1)="1","Ativo",IF(MID(E14,1,1)="2","Passivo","Resultado")) -> Ativo | D14: =IF(MID(E14,10,3)="000","Sintetica","") | E14: 1.1.1.02.0013 | F14: BANCO DO BRASIL - SMART PODS | G14: 0 | I14: 30194.16 | J14: 30194.16 | K14: 0 | M14: =IF(H14="D",G14,-G14) -> 0 | N14: =IF(L14="D",K14,-K14) -> 0
B15: jun/26 | C15: =IF(MID(E15,1,1)="1","Ativo",IF(MID(E15,1,1)="2","Passivo","Resultado")) -> Ativo | D15: =IF(MID(E15,10,3)="000","Sintetica","") | E15: 1.1.1.02.0014 | F15: BANCO SANTANDER - SMART PODS | G15: 0 | I15: 76211.55 | J15: 175971.45 | K15: 99759.9 | L15: C | M15: =IF(H15="D",G15,-G15) -> 0 | N15: =IF(L15="D",K15,-K15) -> -99759.9
B16: jun/26 | C16: =IF(MID(E16,1,1)="1","Ativo",IF(MID(E16,1,1)="2","Passivo","Resultado")) -> Ativo | D16: =IF(MID(E16,10,3)="000","Sintetica","") | E16: 1.1.1.02.0015 | F16: BANCO BOCOM BBM - SMART PODS | G16: 471.4 | H16: D | I16: 0 | J16: 0 | K16: 471.4 | L16: D | M16: =IF(H16="D",G16,-G16) -> 471.4 | N16: =IF(L16="D",K16,-K16) -> 471.4
B17: jun/26 | C17: =IF(MID(E17,1,1)="1","Ativo",IF(MID(E17,1,1)="2","Passivo","Resultado")) -> Ativo | D17: =IF(MID(E17,10,3)="000","Sintetica","") | E17: 1.1.1.02.0016 | F17: BANCO ABC C.C MATRIZ | G17: 267.21 | H17: D | I17: 105091.29 | J17: 102592.6 | K17: 2765.9 | L17: D | M17: =IF(H17="D",G17,-G17) -> 267.21 | N17: =IF(L17="D",K17,-K17) -> 2765.9
B18: jun/26 | C18: =IF(MID(E18,1,1)="1","Ativo",IF(MID(E18,1,1)="2","Passivo","Resultado")) -> Ativo | D18: =IF(MID(E18,10,3)="000","Sintetica","") | E18: 1.1.1.02.0017 | F18: BANCO SOFISA VINC. AG. 19 CC. 14293503 | G18: 781880.95 | H18: D | I18: 153.52 | J18: 181955.06 | K18: 600079.41 | L18: D | M18: =IF(H18="D",G18,-G18) -> 781880.95 | N18: =IF(L18="D",K18,-K18) -> 600079.41
B19: jun/26 | C19: =IF(MID(E19,1,1)="1","Ativo",IF(MID(E19,1,1)="2","Passivo","Resultado")) -> Ativo | D19: =IF(MID(E19,10,3)="000","Sintetica","") | E19: 1.1.1.02.0024 | F19: BANCO SANTANDER - SMART FILIAL | G19: 0 | I19: 1756685.2 | J19: 1757043 | K19: 357.77 | L19: C | M19: =IF(H19="D",G19,-G19) -> 0 | N19: =IF(L19="D",K19,-K19) -> -357.77
B20: jun/26 | C20: =IF(MID(E20,1,1)="1","Ativo",IF(MID(E20,1,1)="2","Passivo","Resultado")) -> Ativo | D20: =IF(MID(E20,10,3)="000","Sintetica","") | E20: 1.1.1.02.0025 | F20: BANCO SOFISA AG. 00019 CC.13649169 MATR | G20: 0 | I20: 90880.34 | J20: 17622.29 | K20: 73258.05 | L20: D | M20: =IF(H20="D",G20,-G20) -> 0 | N20: =IF(L20="D",K20,-K20) -> 73258.05
B21: jun/26 | C21: =IF(MID(E21,1,1)="1","Ativo",IF(MID(E21,1,1)="2","Passivo","Resultado")) -> Ativo | D21: =IF(MID(E21,10,3)="000","Sintetica","") | E21: 1.1.1.02.0026 | F21: BANCO DAYCOVAL - AG. 00019 CC 15147454 | G21: 127.13 | H21: D | I21: 0 | J21: 43.79 | K21: 83.34 | L21: D | M21: =IF(H21="D",G21,-G21) -> 127.13 | N21: =IF(L21="D",K21,-K21) -> 83.34
B22: jun/26 | C22: =IF(MID(E22,1,1)="1","Ativo",IF(MID(E22,1,1)="2","Passivo","Resultado")) -> Ativo | D22: =IF(MID(E22,10,3)="000","Sintetica","") | E22: 1.1.1.02.0028 | F22: BANCO ABC AG.019 CC.23317770 CC FILIAL | G22: 1.54 | H22: D | I22: 1734.41 | J22: 1851.97 | K22: 116.02 | L22: C | M22: =IF(H22="D",G22,-G22) -> 1.54 | N22: =IF(L22="D",K22,-K22) -> -116.02
B23: jun/26 | C23: =IF(MID(E23,1,1)="1","Ativo",IF(MID(E23,1,1)="2","Passivo","Resultado")) -> Ativo | D23: =IF(MID(E23,10,3)="000","Sintetica","") | E23: 1.1.1.02.9999 | F23: BANCOS TRANSFERENCIAS ENTRE FILIAIS | G23: 0 | I23: 426640.15 | J23: 426640.15 | K23: 0 | M23: =IF(H23="D",G23,-G23) -> 0 | N23: =IF(L23="D",K23,-K23) -> 0
B24: jun/26 | C24: =IF(MID(E24,1,1)="1","Ativo",IF(MID(E24,1,1)="2","Passivo","Resultado")) -> Ativo | D24: =IF(MID(E24,10,3)="000","Sintetica","") -> Sintetica | E24: 1.1.1.03.0000 | F24: APLICACOES FINANCEIRAS | G24: 1149020.3 | H24: D | I24: 71.53 | J24: 686.09 | K24: 1148405.8 | L24: D | M24: =IF(H24="D",G24,-G24) -> 1149020.3 | N24: =IF(L24="D",K24,-K24) -> 1148405.8
B25: jun/26 | C25: =IF(MID(E25,1,1)="1","Ativo",IF(MID(E25,1,1)="2","Passivo","Resultado")) -> Ativo | D25: =IF(MID(E25,10,3)="000","Sintetica","") | E25: 1.1.1.03.0011 | F25: ITAU S/A - SMART PODS | G25: 420.41 | H25: D | I25: 71.52 | J25: 491.93 | K25: 0 | M25: =IF(H25="D",G25,-G25) -> 420.41 | N25: =IF(L25="D",K25,-K25) -> 0
B26: jun/26 | C26: =IF(MID(E26,1,1)="1","Ativo",IF(MID(E26,1,1)="2","Passivo","Resultado")) -> Ativo | D26: =IF(MID(E26,10,3)="000","Sintetica","") | E26: 1.1.1.03.0025 | F26: APLIC BANCO ABC - SMART PODS | G26: 1148405.8 | H26: D | I26: 0 | J26: 0 | K26: 1148405.8 | L26: D | M26: =IF(H26="D",G26,-G26) -> 1148405.8 | N26: =IF(L26="D",K26,-K26) -> 1148405.8
B27: jun/26 | C27: =IF(MID(E27,1,1)="1","Ativo",IF(MID(E27,1,1)="2","Passivo","Resultado")) -> Ativo | D27: =IF(MID(E27,10,3)="000","Sintetica","") | E27: 1.1.1.03.0027 | F27: APLICAÇÃO BB RENDE FÁCIL MATRIZ | G27: 194.15 | H27: D | I27: 0.01 | J27: 194.16 | K27: 0 | M27: =IF(H27="D",G27,-G27) -> 194.15 | N27: =IF(L27="D",K27,-K27) -> 0
B28: jun/26 | D28: =IF(MID(E28,10,3)="000","Sintetica","") -> Sintetica | E28: 1.1.2.00.0000 | F28: CREDITOS | G28: 10712086 | H28: D | I28: 869998.15 | J28: 749155.56 | K28: 10832929 | L28: D | M28: =IF(H28="D",G28,-G28) -> 10712086 | N28: =IF(L28="D",K28,-K28) -> 10832929
B29: jun/26 | C29: =IF(MID(E29,1,1)="1","Ativo",IF(MID(E29,1,1)="2","Passivo","Resultado")) -> Ativo | D29: =IF(MID(E29,10,3)="000","Sintetica","") -> Sintetica | E29: 1.1.2.01.0000 | F29: CLIENTES | G29: 10759086 | H29: D | I29: 818931.59 | J29: 697830.41 | K29: 10880187 | L29: D | M29: =IF(H29="D",G29,-G29) -> 10759086 | N29: =IF(L29="D",K29,-K29) -> 10880187
B30: jun/26 | C30: =IF(MID(E30,1,1)="1","Ativo",IF(MID(E30,1,1)="2","Passivo","Resultado")) -> Ativo | D30: =IF(MID(E30,10,3)="000","Sintetica","") -> Sintetica | E30: 1.1.2.01.0001 | F30: CONTAS A RECEBER | G30: 10595294 | H30: D | I30: 802315.34 | J30: 681214.16 | K30: 10716395 | L30: D | M30: =IF(H30="D",G30,-G30) -> 10595294 | N30: =IF(L30="D",K30,-K30) -> 10716395
B31: jun/26 | C31: =IF(MID(E31,1,1)="1","Ativo",IF(MID(E31,1,1)="2","Passivo","Resultado")) -> Ativo | D31: =IF(MID(E31,10,3)="000","Sintetica","") -> Sintetica | E31: 1.1.2.01.0002 | F31: (-) DEVOLUCAO CLIENTES COMPENSAR | G31: 3518166.4 | H31: C | I31: 0 | J31: 0 | K31: 3518166.4 | L31: C | M31: =IF(H31="D",G31,-G31) -> -3518166.4 | N31: =IF(L31="D",K31,-K31) -> -3518166.4
B32: jun/26 | C32: =IF(MID(E32,1,1)="1","Ativo",IF(MID(E32,1,1)="2","Passivo","Resultado")) -> Ativo | D32: =IF(MID(E32,10,3)="000","Sintetica","") -> Sintetica | E32: 1.1.2.01.0003 | F32: ANTECIPACAO DE CLIENTES A RECEBER | G32: 541323.32 | H32: D | I32: 0 | J32: 0 | K32: 541323.32 | L32: D | M32: =IF(H32="D",G32,-G32) -> 541323.32 | N32: =IF(L32="D",K32,-K32) -> 541323.32
B33: jun/26 | C33: =IF(MID(E33,1,1)="1","Ativo",IF(MID(E33,1,1)="2","Passivo","Resultado")) -> Ativo | D33: =IF(MID(E33,10,3)="000","Sintetica","") -> Sintetica | E33: 1.1.2.01.0007 | F33: (-) PROV P/ CRED DE LIQUIDACAO DUVID | G33: 1260020.9 | H33: C | I33: 0 | J33: 0 | K33: 1260020.9 | L33: C | M33: =IF(H33="D",G33,-G33) -> -1260020.9 | N33: =IF(L33="D",K33,-K33) -> -1260020.9
B34: jun/26 | C34: =IF(MID(E34,1,1)="1","Ativo",IF(MID(E34,1,1)="2","Passivo","Resultado")) -> Ativo | D34: =IF(MID(E34,10,3)="000","Sintetica","") -> Sintetica | E34: 1.1.2.01.0008 | F34: PROVISAO SERVIÇOS A REALIZAR | G34: 3426105 | H34: D | I34: 0 | J34: 0 | K34: 3426105 | L34: D | M34: =IF(H34="D",G34,-G34) -> 3426105 | N34: =IF(L34="D",K34,-K34) -> 3426105
B35: jun/26 | C35: =IF(MID(E35,1,1)="1","Ativo",IF(MID(E35,1,1)="2","Passivo","Resultado")) -> Ativo | D35: =IF(MID(E35,10,3)="000","Sintetica","") | E35: 1.1.2.01.0010 | F35: CONTAS A RECEBER INTERCO | G35: 433227.56 | H35: D | I35: 12063 | J35: 12063 | K35: 433227.56 | L35: D | M35: =IF(H35="D",G35,-G35) -> 433227.56 | N35: =IF(L35="D",K35,-K35) -> 433227.56
B36: jun/26 | C36: =IF(MID(E36,1,1)="1","Ativo",IF(MID(E36,1,1)="2","Passivo","Resultado")) -> Ativo | D36: =IF(MID(E36,10,3)="000","Sintetica","") | E36: 1.1.2.01.9998 | F36: CLIENTES - FATURAMENTO ANTECIPADO | G36: 1516728.8 | H36: D | I36: 0 | J36: 4553.25 | K36: 1512175.5 | L36: D | M36: =IF(H36="D",G36,-G36) -> 1516728.8 | N36: =IF(L36="D",K36,-K36) -> 1512175.5
B37: jun/26 | C37: =IF(MID(E37,1,1)="1","Ativo",IF(MID(E37,1,1)="2","Passivo","Resultado")) -> Ativo | D37: =IF(MID(E37,10,3)="000","Sintetica","") | E37: 1.1.2.01.9999 | F37: (-) FATURAMENTO ANTECIPADO | G37: 975405.43 | H37: C | I37: 4553.25 | J37: 0 | K37: 970852.18 | L37: C | M37: =IF(H37="D",G37,-G37) -> -975405.43 | N37: =IF(L37="D",K37,-K37) -> -970852.18
B38: jun/26 | C38: =IF(MID(E38,1,1)="1","Ativo",IF(MID(E38,1,1)="2","Passivo","Resultado")) -> Ativo | D38: =IF(MID(E38,10,3)="000","Sintetica","") -> Sintetica | E38: 1.1.2.02.0000 | F38: CREDITOS DE PESSOAL | G38: 46999.81 | H38: C | I38: 51066.56 | J38: 51325.15 | K38: 47258.4 | L38: C | M38: =IF(H38="D",G38,-G38) -> -46999.81 | N38: =IF(L38="D",K38,-K38) -> -47258.4
B39: jun/26 | C39: =IF(MID(E39,1,1)="1","Ativo",IF(MID(E39,1,1)="2","Passivo","Resultado")) -> Ativo | D39: =IF(MID(E39,10,3)="000","Sintetica","") -> Sintetica | E39: 1.1.2.02.0001 | F39: ADIANTAMENTO DE SALARIOS | G39: 49546.52 | H39: C | I39: 49546.52 | J39: 50003.75 | K39: 50003.75 | L39: C | M39: =IF(H39="D",G39,-G39) -> -49546.52 | N39: =IF(L39="D",K39,-K39) -> -50003.75
B40: jun/26 | D40: =IF(MID(E40,10,3)="000","Sintetica","") -> Sintetica | E40: 1.1.2.02.0002 | F40: ADIANTAMENTO DE FERIAS | G40: 303.63 | H40: C | I40: 303.63 | J40: 271.89 | K40: 271.89 | L40: C | M40: =IF(H40="D",G40,-G40) -> -303.63 | N40: =IF(L40="D",K40,-K40) -> -271.89
B41: jun/26 | D41: =IF(MID(E41,10,3)="000","Sintetica","") -> Sintetica | E41: 1.1.2.02.0004 | F41: EMPRESTIMO COLABORADORES | G41: 2850.34 | H41: D | I41: 1216.41 | J41: 1049.51 | K41: 3017.24 | L41: D | M41: =IF(H41="D",G41,-G41) -> 2850.34 | N41: =IF(L41="D",K41,-K41) -> 3017.24
...

Sheet 01.Razão
M5: =SUBTOTAL(9,M7:M120) -> -280060
B6: Período | C6: Conta | D6: Conta + Descrição | E6: Data | F6: LOTE/SUB/DOC/LINHA | G6: HISTORICO | H6: C/PARTIDA | I6: FL | J6: C CUSTO | K6: DEBITO | L6: CREDITO | M6: Valor | N6: Obs.
B7: 2021 | C7: 2.1.1.05.0005 | D7: 2.1.1.05.0005 - PROVISAO BONUS A PAGAR | E7: 44227 | F7: 000001001000014001 | G7: PROV BONUS A PAGAR ACIONISTA | H7: 4.1.1.01.0026 | I7: 0301 | K7: 0 | L7: 22500 | M7: =K7-L7 -> -22500 | N7: Efeito zero
B8: 2021 | C8: =MID(D8,1,12) -> 2.1.1.05.000 | D8: 2.1.1.05.0005 - PROVISAO BONUS A PAGAR | E8: 44255 | F8: 000001001000001001 | G8: PROV BONUS A PAGAR ACIONISTA | H8: 4.1.1.01.0026 | I8: 0301 | K8: 0 | L8: 22500 | M8: =K8-L8 -> -22500 | N8: Efeito zero
B9: 2021 | C9: =MID(D9,1,12) -> 2.1.1.05.000 | D9: 2.1.1.05.0005 - PROVISAO BONUS A PAGAR | E9: 44286 | F9: 000001001000014001 | G9: PROV BONUS A PAGAR ACIONISTA | H9: 4.1.1.01.0026 | I9: 0301 | K9: 0 | L9: 22500 | M9: =K9-L9 -> -22500 | N9: Efeito zero
B10: 2021 | C10: =MID(D10,1,12) -> 2.1.1.05.000 | D10: 2.1.1.05.0005 - PROVISAO BONUS A PAGAR | E10: 44316 | F10: 000001001000012001 | G10: PROVISAO DE BONUS MES MARÇO E ABRIL | H10: 4.1.1.01.0026 | I10: 0301 | K10: 0 | L10: 40500 | M10: =K10-L10 -> -40500 | N10: Efeito zero
B11: 2021 | C11: =MID(D11,1,12) -> 2.1.1.05.000 | D11: 2.1.1.05.0005 - PROVISAO BONUS A PAGAR | E11: 44347 | F11: 001010001000001001 | G11: PROVISAO DE BONUS MES MAIO-21 | H11: 4.1.1.01.0026 | I11: 0301 | K11: 0 | L11: 27000 | M11: =K11-L11 -> -27000 | N11: Efeito zero
B12: 2021 | C12: =MID(D12,1,12) -> 2.1.1.05.000 | D12: 2.1.1.05.0005 - PROVISAO BONUS A PAGAR | E12: 44377 | F12: 000001001000001005 | G12: PROVISAO DE BONUS JUN 2021 | H12: 4.1.1.01.0026 | I12: 0301 | K12: 0 | L12: 27000 | M12: =K12-L12 -> -27000 | N12: Efeito zero
B13: 2021 | C13: =MID(D13,1,12) -> 2.1.1.05.000 | D13: 2.1.1.05.0005 - PROVISAO BONUS A PAGAR | E13: 44407 | F13: 000001001000008001 | G13: PROV PROVISAO DE BONUS | H13: 4.1.1.01.0026 | I13: 0301 | K13: 0 | L13: 27000 | M13: =K13-L13 -> -27000 | N13: Efeito zero
B14: 2021 | C14: =MID(D14,1,12) -> 2.1.1.05.000 | D14: 2.1.1.05.0005 - PROVISAO BONUS A PAGAR | E14: 44439 | F14: 000001001000001001 | G14: PROV PROVISAO DE BONUS | H14: 4.1.1.01.0026 | I14: 0301 | K14: 0 | L14: 27000 | M14: =K14-L14 -> -27000 | N14: Efeito zero
B15: 2021 | C15: =MID(D15,1,12) -> 2.1.1.05.000 | D15: 2.1.1.05.0005 - PROVISAO BONUS A PAGAR | E15: 44467 | F15: 000001001000005001 | G15: PROV PROVISAO DE BONUS | H15: 4.1.1.01.0026 | I15: 0301 | K15: 0 | L15: 27000 | M15: =K15-L15 -> -27000 | N15: Efeito zero
B16: 2021 | C16: =MID(D16,1,12) -> 2.1.1.05.000 | D16: 2.1.1.05.0005 - PROVISAO BONUS A PAGAR | E16: 44498 | F16: 000001001000002001 | G16: PROV PROVISAO DE BONUS | H16: 4.1.1.01.0026 | I16: 0301 | K16: 0 | L16: 27000 | M16: =K16-L16 -> -27000 | N16: Efeito zero
B17: 2021 | C17: =MID(D17,1,12) -> 2.1.1.05.000 | D17: 2.1.1.05.0005 - PROVISAO BONUS A PAGAR | E17: 44529 | F17: 000001001000002001 | G17: PROV PROVISAO DE BONUS | H17: 4.1.1.01.0026 | I17: 0301 | K17: 0 | L17: 27000 | M17: =K17-L17 -> -27000 | N17: Efeito zero
B18: 2021 | C18: =MID(D18,1,12) -> 2.1.1.05.000 | D18: 2.1.1.05.0005 - PROVISAO BONUS A PAGAR | E18: 44560 | F18: 000001001000002001 | G18: PROV PROVISAO DE BONUS | H18: 4.1.1.01.0026 | I18: 0301 | K18: 0 | L18: 27000 | M18: =K18-L18 -> -27000 | N18: Efeito zero
B19: 2021 | C19: =MID(D19,1,12) -> 2.1.1.05.000 | D19: 2.1.1.05.0005 - PROVISAO BONUS A PAGAR | E19: 44561 | F19: 000001001000032001 | G19: EST PROV BONUS | H19: 4.1.1.01.0026 | I19: 0301 | K19: 324000 | L19: 0 | M19: =K19-L19 -> 324000 | N19: Efeito zero
... B34: 2022 | C34: =MID(D34,1,12) -> 2.1.1.05.000 | D34: 2.1.1.05.0005 - PROVISAO BONUS A PAGAR | E34: 44925 | F34: 000001001000152001 | G34: PROV EST BONUS | H34: 4.1.1.01.0026 | I34: 0301 | K34: 358279.2 | L34: 0 | M34: =K34-L34 -> 358279.2 | N34: Efeito zero
B35: 2023 | C35: =MID(D35,1,12) -> 2.1.1.05.000 | D35: 2.1.1.05.0005 - PROVISAO BONUS A PAGAR | E35: 44957 | F35: 000001001000024001 | G35: PROV BONUS | H35: 4.1.1.01.0026 | I35: 0301 | K35: 0 | L35: 66439 | M35: =K35-L35 -> -66439
B36: 2023 | C36: =MID(D36,1,12) -> 2.1.1.05.000 | D36: 2.1.1.05.0005 - PROVISAO BONUS A PAGAR | E36: 44985 | F36: 000001001000012001 | G36: PROV BONUS | H36: 4.1.1.01.0026 | I36: 0301 | K36: 0 | L36: 66439 | M36: =K36-L36 -> -66439
B37: 2023 | C37: =MID(D37,1,12) -> 2.1.1.05.000 | D37: 2.1.1.05.0005 - PROVISAO BONUS A PAGAR | E37: 45016 | F37: 000001001000005001 | G37: PROV BONUS | H37: 4.1.1.01.0026 | I37: 0301 | K37: 0 | L37: 66439 | M37: =K37-L37 -> -66439
B38: 2023 | C38: =MID(D38,1,12) -> 2.1.1.05.000 | D38: 2.1.1.05.0005 - PROVISAO BONUS A PAGAR | E38: 45016 | F38: 000001001000016001 | G38: PROV BONUS | H38: 4.1.1.01.0026 | I38: 0301 | K38: 0 | L38: 1 | M38: =K38-L38 -> -1
B39: 2023 | C39: =MID(D39,1,12) -> 2.1.1.05.000 | D39: 2.1.1.05.0005 - PROVISAO BONUS A PAGAR | E39: 45046 | F39: 000001001000016001 | G39: PROV BONUS | H39: 4.1.1.01.0026 | I39: 0301 | K39: 0 | L39: 66440 | M39: =K39-L39 -> -66440
B40: 2023 | C40: =MID(D40,1,12) -> 2.1.1.05.000 | D40: 2.1.1.05.0005 - PROVISAO BONUS A PAGAR | E40: 45077 | F40: 000001001011342001 | G40: VLR PROVISAO BONUS | H40: 4.1.1.01.0026 | I40: 0301 | K40: 0 | L40: 66439 | M40: =K40-L40 -> -66439
B41: 2023 | C41: =MID(D41,1,12) -> 2.1.1.05.000 | D41: 2.1.1.05.0005 - PROVISAO BONUS A PAGAR | E41: 45107 | F41: 000001001000007002 | G41: VLR PROVISAO BONUS | H41: 4.1.1.01.0026 | I41: 0301 | K41: 0 | L41: 7639 | M41: =K41-L41 -> -7639
B42: 2023 | C42: =MID(D42,1,12) -> 2.1.1.05.000 | D42: 2.1.1.05.0005 - PROVISAO BONUS A PAGAR | E42: 45138 | F42: 000001001000015002 | G42: VLR PROVISAO BONUS | H42: 4.1.1.01.0026 | I42: 0301 | K42: 0 | L42: 56639 | M42: =K42-L42 -> -56639
B43: 2023 | C43: =MID(D43,1,12) -> 2.1.1.05.000 | D43: 2.1.1.05.0005 - PROVISAO BONUS A PAGAR | E43: 45169 | F43: 000001001000003002 | G43: VLR PROVISAO BONUS | H43: 4.1.1.01.0026 | I43: 0301 | K43: 0 | L43: 56640 | M43: =K43-L43 -> -56640
B44: 2023 | C44: =MID(D44,1,12) -> 2.1.1.05.000 | D44: 2.1.1.05.0005 - PROVISAO BONUS A PAGAR | E44: 45199 | F44: 000001001000003002 | G44: VLR PROVISAO BONUS | H44: 4.1.1.01.0026 | I44: 0301 | K44: 0 | L44: 56639 | M44: =K44-L44 -> -56639
B45: 2023 | C45: =MID(D45,1,12) -> 2.1.1.05.000 | D45: 2.1.1.05.0005 - PROVISAO BONUS A PAGAR | E45: 45230 | F45: 000001001000005002 | G45: VLR PROVISAO BONUS | H45: 4.1.1.01.0026 | I45: 0301 | K45: 0 | L45: 56640 | M45: =K45-L45 -> -56640
B46: 2023 | C46: =MID(D46,1,12) -> 2.1.1.05.000 | D46: 2.1.1.05.0005 - PROVISAO BONUS A PAGAR | E46: 45260 | F46: 000001001000006002 | G46: VLR PROVISAO BONUS | H46: 4.1.1.01.0026 | I46: 0301 | K46: 116611 | L46: 0 | M46: =K46-L46 -> 116611
... B52: 2024 | C52: =MID(D52,1,12) -> 2.1.1.05.000 | D52: 2.1.1.05.0005 - PROVISAO BONUS A PAGAR | E52: 45566 | F52: 000001001000001001 | G52: VLR PROVISAO DE BONUS | H52: 4.1.1.01.0026 | I52: 0301 | K52: 56880 | L52: 0 | M52: =K52-L52 -> 56880
B53: 2024 | C53: =MID(D53,1,12) -> 2.1.1.05.000 | D53: 2.1.1.05.0005 - PROVISAO BONUS A PAGAR | E53: 45412 | F53: 99999B001000002001 | G53: 313 - PREMIO | H53: 4.1.1.01.0020 | I53: 0301 | J53: 0.3.5.000001 | K53: 55372.32 | L53: 0 | M53: =K53-L53 -> 55372.32
B54: 2024 | C54: =MID(D54,1,12) -> 2.1.1.05.000 | D54: 2.1.1.05.0005 - PROVISAO BONUS A PAGAR | E54: 45595 | F54: 000001001000003001 | G54: VLR EST PREVISAO BONUS | H54: 4.1.1.01.0026 | I54: 0302 | K54: 42232 | L54: 0 | M54: =K54-L54 -> 42232
B55: 2024 | C55: =MID(D55,1,12) -> 2.1.1.05.000 | D55: 2.1.1.05.0005 - PROVISAO BONUS A PAGAR | E55: 45536 | F55: 000001001000003001 | G55: VLR PROVISAO DE BONUS | H55: 4.1.1.01.0026 | I55: 0301 | K55: 40797 | L55: 0 | M55: =K55-L55 -> 40797
B56: 2024 | C56: =MID(D56,1,12) -> 2.1.1.05.000 | D56: 2.1.1.05.0005 - PROVISAO BONUS A PAGAR | E56: 45412 | F56: 000001001000007002 | G56: 313 - PRÊMIO | H56: 3.1.1.04.0020 | I56: 0302 | K56: 31263.99 | L56: 0 | M56: =K56-L56 -> 31263.99
B57: 2024 | C57: =MID(D57,1,12) -> 2.1.1.05.000 | D57: 2.1.1.05.0005 - PROVISAO BONUS A PAGAR | E57: 45412 | F57: 000001001000014004 | G57: 313 - PREMIO | H57: 4.2.1.01.0020 | I57: 0301 | K57: 27273.52 | L57: 0 | M57: =K57-L57 -> 27273.52
B58: 2024 | C58: =MID(D58,1,12) -> 2.1.1.05.000 | D58: 2.1.1.05.0005 - PROVISAO BONUS A PAGAR | E58: 45412 | F58: 000001001000014003 | G58: 313 - PREMIO | H58: 3.1.1.04.0020 | I58: 0301 | K58: 25240.72 | L58: 0 | M58: =K58-L58 -> 25240.72
B59: 2024 | C59: =MID(D59,1,12) -> 2.1.1.05.000 | D59: 2.1.1.05.0005 - PROVISAO BONUS A PAGAR | E59: 45536 | F59: 000001001000002001 | G59: VLR PROVISAO BONUS | H59: 4.1.1.01.0026 | I59: 0302 | K59: 24648 | L59: 0 | M59: =K59-L59 -> 24648
B60: 2024 | C60: =MID(D60,1,12) -> 2.1.1.05.000 | D60: 2.1.1.05.0005 - PROVISAO BONUS A PAGAR | E60: 45412 | F60: 000001001000007005 | G60: 313 - PRÊMIO | H60: 3.1.1.02.0020 | I60: 0302 | J60: 0.1.1.000001 | K60: 24529.8 | L60: 0 | M60: =K60-L60 -> 24529.8
B61: 2024 | C61: =MID(D61,1,12) -> 2.1.1.05.000 | D61: 2.1.1.05.0005 - PROVISAO BONUS A PAGAR | E61: 45412 | F61: 000001001000014001 | G61: 313 - PREMIO | H61: 4.2.1.01.0020 | I61: 0301 | J61: 0.3.7.000002 | K61: 23427.51 | L61: 0 | M61: =K61-L61 -> 23427.51
B62: 2024 | C62: =MID(D62,1,12) -> 2.1.1.05.000 | D62: 2.1.1.05.0005 - PROVISAO BONUS A PAGAR | E62: 45412 | F62: 000001001000007004 | G62: 313 - PRÊMIO | H62: 3.1.1.04.0020 | I62: 0302 | K62: 22791.79 | L62: 0 | M62: =K62-L62 -> 22791.79
B63: 2024 | C63: =MID(D63,1,12) -> 2.1.1.05.000 | D63: 2.1.1.05.0005 - PROVISAO BONUS A PAGAR | E63: 45412 | F63: 000001001000014002 | G63: 313 - PREMIO | H63: 4.1.1.01.0020 | I63: 0301 | K63: 21166.53 | L63: 0 | M63: =K63-L63 -> 21166.53
...

Sheet 02.Suporte
R1: Lançamento
C4: Mês | J4: x
C5: Acumulado | E5: x | F5: x | G5: x | H5: x | I5: x | J5: x
B6: BU | C6: Provisão e BU | E6: Jan | F6: Fev | G6: Mar | H6: Abr | I6: Mai | J6: Jun | K6: Jul | L6: Ago | M6: Set | N6: Out | O6: Nov | P6: Dez | Q6: Saldo | S6: Data | T6: DB | U6: CR | V6: Valor | W6: C.C | X6: C.C | Y6: Histórico
B7: Ambar | C7: Bônus | E7: 99320 | F7: 99320 | G7: 99320 | H7: 99320 | I7: 99320 | J7: 99320 | K7: 99320 | L7: 99320 | M7: 99320 | N7: 99320 | O7: 99320 | P7: 99320 | Q7: =SUMIFS($E$7:$P$7,$E$5:$P$5,"x") -> 595920 | S7: 46203 | T7: 5.1.3.80.140 | U7: 2.1.5.10.050 | V7: =SUMIFS($E$7:$P$7,$E$4:$P$4,"x") -> 99320 | W7: 5.3.1.7 | X7: 5.3.1.7 | Y7: PROVISAO BONUS POLAR 06/2026

Sheet 03.Conciliação
B6: Período | C6: BU | D6: Classificação | E6: Valor | F6: Obs.
B7: 2023 | C7: Ambar Tech | D7: Provisão Bônus - 2023 | E7: =SUMIFS('01.Razão'!$M:$M,'01.Razão'!$N:$N,'03.Conciliação'!$D7) -> 0
B8: 2023 | C8: Ambar Tech | D8: Reversão Bônus - 2023 | E8: =SUMIFS('01.Razão'!$M:$M,'01.Razão'!$N:$N,'03.Conciliação'!$D8) -> 0
B10: 2023 | C10: Ambar Tech | D10: Saldo | E10: =SUM(E7:E8) -> 0 | F10: Saldo baixado a maior referente a provisão de Bônus - 2023
B13: 2024 | C13: Ambar Tech | D13: Provisão Bônus - 2024 | E13: =SUMIFS('01.Razão'!$M:$M,'01.Razão'!$N:$N,'03.Conciliação'!$D13) -> 0
B14: 2024 | C14: Ambar Tech | D14: Reversão Bônus - 2024 | E14: =SUMIFS('01.Razão'!$M:$M,'01.Razão'!$N:$N,'03.Conciliação'!$D14) -> 0
B16: 2024 | C16: Ambar Tech | D16: Saldo | E16: =SUM(E13:E14) -> 0 | F16: Saldo em aberto referente a Provisão de Bônus - 2024
B18: 2025 | C18: Ambar Tech | D18: Provisão Bônus - 2025 | E18: =SUMIFS('01.Razão'!$M:$M,'01.Razão'!$N:$N,'03.Conciliação'!$D18) -> 0
B19: 2025 | C19: Ambar Tech | D19: Reversão Bônus - 2025 | E19: =SUMIFS('01.Razão'!$M:$M,'01.Razão'!$N:$N,'03.Conciliação'!$D19) -> 0
B21: 2025 | C21: Ambar Tech | D21: Saldo | E21: =SUM(E18:E19) -> 0 | F21: Saldo em aberto referente a Provisão de Bônus - 2025
B23: 2026 | C23: Ambar Tech | D23: Provisão Bônus - 2026 | E23: =SUMIFS('01.Razão'!$M:$M,'01.Razão'!$N:$N,'03.Conciliação'!$D23) -> 0
B24: 2026 | C24: Ambar Tech | D24: Reversão Bônus - 2026 | E24: =SUMIFS('01.Razão'!$M:$M,'01.Razão'!$N:$N,'03.Conciliação'!$D24) -> 0
B26: 2026 | C26: Ambar Tech | D26: Saldo | E26: =SUM(E23:E24) -> 0 | F26: Saldo em aberto referente a Provisão de Bônus - 2026
B28: 2026 | C28: Ambar Tech | D28: Saldo - Passivo | E28: =SUM(E26,E21,E16,E10) -> 0
